Workbook

Sheet Dashboard BI
A1: DASHBOARD EXECUTIVO / BI - MONITORAMENTO DE CÂMERAS EMBARCAÇÕES
A3: Resumo consolidado dos 12 meses. Os indicadores são alimentados automaticamente pelas abas mensais.
A5: DISPONIBILIDADE GERAL | D5: TOTAL OFFLINE | G5: EVENTOS REGISTRADOS | J5: NÃO VERIFICADOS
A6: =IFERROR(SUM(C11:C22)/(SUM(C11:C22)+SUM(D11:D22)+SUM(E11:E22)),0) -> 1 | D6: =SUM(D11:D22) -> 0 | G6: =SUM(H11:H22) -> 0 | J6: =SUM(F11:F22) -> 25667
A10: Mês | B10: Total Verificações | C10: Online | D10: Offline | E10: Manutenção | F10: Não Verificado | G10: Disponibilidade | H10: Eventos | J10: Status | K10: Consolidado
A11: Janeiro | B11: =C11+D11+E11+F11 -> 2139 | C11: =COUNTIF(Janeiro!F6:H718,"Online") -> 1 | D11: =COUNTIF(Janeiro!F6:H718,"Offline") -> 0 | E11: =COUNTIF(Janeiro!F6:H718,"Manutenção") -> 0 | F11: =COUNTIF(Janeiro!F6:H718,"Não verificado") -> 2138 | G11: =IFERROR(C11/(C11+D11+E11),0) -> 1 | H11: =COUNTA(Janeiro!I6:J718) -> 0 | J11: Online | K11: =SUM(C11:C22) -> 1
A12: Fevereiro | B12: =C12+D12+E12+F12 -> 2139 | C12: =COUNTIF(Fevereiro!F6:H718,"Online") -> 0 | D12: =COUNTIF(Fevereiro!F6:H718,"Offline") -> 0 | E12: =COUNTIF(Fevereiro!F6:H718,"Manutenção") -> 0 | F12: =COUNTIF(Fevereiro!F6:H718,"Não verificado") -> 2139 | G12: =IFERROR(C12/(C12+D12+E12),0) -> 0 | H12: =COUNTA(Fevereiro!I6:J718) -> 0 | J12: Offline | K12: =SUM(D11:D22) -> 0
A13: Março | B13: =C13+D13+E13+F13 -> 2139 | C13: =COUNTIF(Março!F6:H718,"Online") -> 0 | D13: =COUNTIF(Março!F6:H718,"Offline") -> 0 | E13: =COUNTIF(Março!F6:H718,"Manutenção") -> 0 | F13: =COUNTIF(Março!F6:H718,"Não verificado") -> 2139 | G13: =IFERROR(C13/(C13+D13+E13),0) -> 0 | H13: =COUNTA(Março!I6:J718) -> 0 | J13: Manutenção | K13: =SUM(E11:E22) -> 0
A14: Abril | B14: =C14+D14+E14+F14 -> 2139 | C14: =COUNTIF(Abril!F6:H718,"Online") -> 0 | D14: =COUNTIF(Abril!F6:H718,"Offline") -> 0 | E14: =COUNTIF(Abril!F6:H718,"Manutenção") -> 0 | F14: =COUNTIF(Abril!F6:H718,"Não verificado") -> 2139 | G14: =IFERROR(C14/(C14+D14+E14),0) -> 0 | H14: =COUNTA(Abril!I6:J718) -> 0 | J14: Não verificado | K14: =SUM(F11:F22) -> 25667
A15: Maio | B15: =C15+D15+E15+F15 -> 2139 | C15: =COUNTIF(Maio!F6:H718,"Online") -> 0 | D15: =COUNTIF(Maio!F6:H718,"Offline") -> 0 | E15: =COUNTIF(Maio!F6:H718,"Manutenção") -> 0 | F15: =COUNTIF(Maio!F6:H718,"Não verificado") -> 2139 | G15: =IFERROR(C15/(C15+D15+E15),0) -> 0 | H15: =COUNTA(Maio!I6:J718) -> 0
A16: Junho | B16: =C16+D16+E16+F16 -> 2139 | C16: =COUNTIF(Junho!F6:H718,"Online") -> 0 | D16: =COUNTIF(Junho!F6:H718,"Offline") -> 0 | E16: =COUNTIF(Junho!F6:H718,"Manutenção") -> 0 | F16: =COUNTIF(Junho!F6:H718,"Não verificado") -> 2139 | G16: =IFERROR(C16/(C16+D16+E16),0) -> 0 | H16: =COUNTA(Junho!I6:J718) -> 0
A17: Julho | B17: =C17+D17+E17+F17 -> 2139 | C17: =COUNTIF(Julho!F6:H718,"Online") -> 0 | D17: =COUNTIF(Julho!F6:H718,"Offline") -> 0 | E17: =COUNTIF(Julho!F6:H718,"Manutenção") -> 0 | F17: =COUNTIF(Julho!F6:H718,"Não verificado") -> 2139 | G17: =IFERROR(C17/(C17+D17+E17),0) -> 0 | H17: =COUNTA(Julho!I6:J718) -> 0
A18: Agosto | B18: =C18+D18+E18+F18 -> 2139 | C18: =COUNTIF(Agosto!F6:H718,"Online") -> 0 | D18: =COUNTIF(Agosto!F6:H718,"Offline") -> 0 | E18: =COUNTIF(Agosto!F6:H718,"Manutenção") -> 0 | F18: =COUNTIF(Agosto!F6:H718,"Não verificado") -> 2139 | G18: =IFERROR(C18/(C18+D18+E18),0) -> 0 | H18: =COUNTA(Agosto!I6:J718) -> 0
A19: Setembro | B19: =C19+D19+E19+F19 -> 2139 | C19: =COUNTIF(Setembro!F6:H718,"Online") -> 0 | D19: =COUNTIF(Setembro!F6:H718,"Offline") -> 0 | E19: =COUNTIF(Setembro!F6:H718,"Manutenção") -> 0 | F19: =COUNTIF(Setembro!F6:H718,"Não verificado") -> 2139 | G19: =IFERROR(C19/(C19+D19+E19),0) -> 0 | H19: =COUNTA(Setembro!I6:J718) -> 0
A20: Outubro | B20: =C20+D20+E20+F20 -> 2139 | C20: =COUNTIF(Outubro!F6:H718,"Online") -> 0 | D20: =COUNTIF(Outubro!F6:H718,"Offline") -> 0 | E20: =COUNTIF(Outubro!F6:H718,"Manutenção") -> 0 | F20: =COUNTIF(Outubro!F6:H718,"Não verificado") -> 2139 | G20: =IFERROR(C20/(C20+D20+E20),0) -> 0 | H20: =COUNTA(Outubro!I6:J718) -> 0
A21: Novembro | B21: =C21+D21+E21+F21 -> 2139 | C21: =COUNTIF(Novembro!F6:H718,"Online") -> 0 | D21: =COUNTIF(Novembro!F6:H718,"Offline") -> 0 | E21: =COUNTIF(Novembro!F6:H718,"Manutenção") -> 0 | F21: =COUNTIF(Novembro!F6:H718,"Não verificado") -> 2139 | G21: =IFERROR(C21/(C21+D21+E21),0) -> 0 | H21: =COUNTA(Novembro!I6:J718) -> 0
A22: Dezembro | B22: =C22+D22+E22+F22 -> 2139 | C22: =COUNTIF(Dezembro!F6:H718,"Online") -> 0 | D22: =COUNTIF(Dezembro!F6:H718,"Offline") -> 0 | E22: =COUNTIF(Dezembro!F6:H718,"Manutenção") -> 0 | F22: =COUNTIF(Dezembro!F6:H718,"Não verificado") -> 2139 | G22: =IFERROR(C22/(C22+D22+E22),0) -> 0 | H22: =COUNTA(Dezembro!I6:J718) -> 0

Sheet Configurações
A1: CONFIGURAÇÕES GERAIS - MONITORAMENTO DE CÂMERAS
A3: Ano Base | B3: 2026 | D3: Status | E3: Descrição
A4: Horários de verificação | B4: 10:00 | 13:00 | 16:00 | D4: Online | E4: Câmera funcionando no horário verificado
D5: Offline | E5: Câmera indisponível no horário verificado
A6: ID | B6: Nome da Câmera | C6: Embarcação/Local | D6: Status de Uso | E6: Observação
A7: CAM 01 | B7: BARU ANDES | D7: Ativa
A8: CAM 02 | B8: Câmera 02 | D8: Ativa
A9: CAM 03 | B9: Câmera 03 | D9: Ativa
A10: CAM 04 | B10: Câmera 04 | D10: Ativa
A11: CAM 05 | B11: Câmera 05 | D11: Ativa
A12: CAM 06 | B12: Câmera 06 | D12: Ativa
A13: CAM 07 | B13: Câmera 07 | D13: Ativa
A14: CAM 08 | B14: Câmera 08 | D14: Ativa
A15: CAM 09 | B15: Câmera 09 | D15: Ativa
A16: CAM 10 | B16: Câmera 10 | D16: Ativa
A17: CAM 11 | B17: Câmera 11 | D17: Ativa
A18: CAM 12 | B18: Câmera 12 | D18: Ativa
... A29: CAM 23 | B29: Reserva/Futura 10 | D29: Futura
A31: ALTERE OS NOMES DAS CÂMERAS APENAS NESTA ABA. TODOS OS MESES SÃO ATUALIZADOS AUTOMATICAMENTE.

Sheet Janeiro
A1: CONTROLE DE MONITORAMENTO DE CÂMERAS - JANEIRO
A2: Status por horário: Online / Offline / Manutenção / Não verificado. Campo livre para evento técnico e comportamento do colaborador.
M4: RESUMO DO MÊS
A5: Data | B5: Dia | C5: ID | D5: Nome da Câmera | E5: Embarcação/Local | F5: 10:00 | G5: 13:00 | H5: 16:00 | I5: Evento Técnico Online/Offline | J5: Comportamento do Colaborador | K5: Responsável | M5: Indicador | N5: Total | O5: % | P5: Meta | Q5: Observação
A6: =DATE(Configurações!$B$3,1,1) -> 46023 | B6: =TEXT(A6,"ddd") -> qui | C6: =Configurações!$A$7 -> CAM 01 | D6: =Configurações!$B$7 -> BARU ANDES | E6: =Configurações!$C$7 -> 0 | F6: Online | G6: Não verificado | H6: Não verificado | M6: Online | N6: =COUNTIF(F6:H718,"Online") -> 1 | O6: =IFERROR(N6/(N6+N7+N8),0) -> 1 | P6: >=95%
A7: =DATE(Configurações!$B$3,1,1) -> 46023 | B7: =TEXT(A7,"ddd") -> qui | C7: =Configurações!$A$8 -> CAM 02 | D7: =Configurações!$B$8 -> Câmera 02 | E7: =Configurações!$C$8 -> 0 | F7: Não verificado | G7: Não verificado | H7: Não verificado | M7: Offline | N7: =COUNTIF(F6:H718,"Offline") -> 0 | O7: =IFERROR(N7/(N6+N7+N8),0) -> 0 | P7: <=5%
A8: =DATE(Configurações!$B$3,1,1) -> 46023 | B8: =TEXT(A8,"ddd") -> qui | C8: =Configurações!$A$9 -> CAM 03 | D8: =Configurações!$B$9 -> Câmera 03 | E8: =Configurações!$C$9 -> 0 | F8: Não verificado | G8: Não verificado | H8: Não verificado | M8: Manutenção | N8: =COUNTIF(F6:H718,"Manutenção") -> 0 | O8: =IFERROR(N8/(N6+N7+N8),0) -> 0
A9: =DATE(Configurações!$B$3,1,1) -> 46023 | B9: =TEXT(A9,"ddd") -> qui | C9: =Configurações!$A$10 -> CAM 04 | D9: =Configurações!$B$10 -> Câmera 04 | E9: =Configurações!$C$10 -> 0 | F9: Não verificado | G9: Não verificado | H9: Não verificado | M9: Não verificado | N9: =COUNTIF(F6:H718,"Não verificado") -> 2138 | O9: =IFERROR(N9/(N6+N7+N8+N9),0) -> 0.99953249 | P9: zerar no fechamento
A10: =DATE(Configurações!$B$3,1,1) -> 46023 | B10: =TEXT(A10,"ddd") -> qui | C10: =Configurações!$A$11 -> CAM 05 | D10: =Configurações!$B$11 -> Câmera 05 | E10: =Configurações!$C$11 -> 0 | F10: Não verificado | G10: Não verificado | H10: Não verificado | M10: Eventos registrados | N10: =COUNTA(I6:J718) -> 0
A11: =DATE(Configurações!$B$3,1,1) -> 46023 | B11: =TEXT(A11,"ddd") -> qui | C11: =Configurações!$A$12 -> CAM 06 | D11: =Configurações!$B$12 -> Câmera 06 | E11: =Configurações!$C$12 -> 0 | F11: Não verificado | G11: Não verificado | H11: Não verificado
A12: =DATE(Configurações!$B$3,1,1) -> 46023 | B12: =TEXT(A12,"ddd") -> qui | C12: =Configurações!$A$13 -> CAM 07 | D12: =Configurações!$B$13 -> Câmera 07 | E12: =Configurações!$C$13 -> 0 | F12: Não verificado | G12: Não verificado | H12: Não verificado
A13: =DATE(Configurações!$B$3,1,1) -> 46023 | B13: =TEXT(A13,"ddd") -> qui | C13: =Configurações!$A$14 -> CAM 08 | D13: =Configurações!$B$14 -> Câmera 08 | E13: =Configurações!$C$14 -> 0 | F13: Não verificado | G13: Não verificado | H13: Não verificado
A14: =DATE(Configurações!$B$3,1,1) -> 46023 | B14: =TEXT(A14,"ddd") -> qui | C14: =Configurações!$A$15 -> CAM 09 | D14: =Configurações!$B$15 -> Câmera 09 | E14: =Configurações!$C$15 -> 0 | F14: Não verificado | G14: Não verificado | H14: Não verificado
A15: =DATE(Configurações!$B$3,1,1) -> 46023 | B15: =TEXT(A15,"ddd") -> qui | C15: =Configurações!$A$16 -> CAM 10 | D15: =Configurações!$B$16 -> Câmera 10 | E15: =Configurações!$C$16 -> 0 | F15: Não verificado | G15: Não verificado | H15: Não verificado
A16: =DATE(Configurações!$B$3,1,1) -> 46023 | B16: =TEXT(A16,"ddd") -> qui | C16: =Configurações!$A$17 -> CAM 11 | D16: =Configurações!$B$17 -> Câmera 11 | E16: =Configurações!$C$17 -> 0 | F16: Não verificado | G16: Não verificado | H16: Não verificado
A17: =DATE(Configurações!$B$3,1,1) -> 46023 | B17: =TEXT(A17,"ddd") -> qui | C17: =Configurações!$A$18 -> CAM 12 | D17: =Configurações!$B$18 -> Câmera 12 | E17: =Configurações!$C$18 -> 0 | F17: Não verificado | G17: Não verificado | H17: Não verificado
A18: =DATE(Configurações!$B$3,1,1) -> 46023 | B18: =TEXT(A18,"ddd") -> qui | C18: =Configurações!$A$19 -> CAM 13 | D18: =Configurações!$B$19 -> Câmera 13 | E18: =Configurações!$C$19 -> 0 | F18: Não verificado | G18: Não verificado | H18: Não verificado
A19: =DATE(Configurações!$B$3,1,1) -> 46023 | B19: =TEXT(A19,"ddd") -> qui | C19: =Configurações!$A$20 -> CAM 14 | D19: =Configurações!$B$20 -> Reserva/Futura 01 | E19: =Configurações!$C$20 -> 0 | F19: Não verificado | G19: Não verificado | H19: Não verificado
A20: =DATE(Configurações!$B$3,1,1) -> 46023 | B20: =TEXT(A20,"ddd") -> qui | C20: =Configurações!$A$21 -> CAM 15 | D20: =Configurações!$B$21 -> Reserva/Futura 02 | E20: =Configurações!$C$21 -> 0 | F20: Não verificado | G20: Não verificado | H20: Não verificado
A21: =DATE(Configurações!$B$3,1,1) -> 46023 | B21: =TEXT(A21,"ddd") -> qui | C21: =Configurações!$A$22 -> CAM 16 | D21: =Configurações!$B$22 -> Reserva/Futura 03 | E21: =Configurações!$C$22 -> 0 | F21: Não verificado | G21: Não verificado | H21: Não verificado
A22: =DATE(Configurações!$B$3,1,1) -> 46023 | B22: =TEXT(A22,"ddd") -> qui | C22: =Configurações!$A$23 -> CAM 17 | D22: =Configurações!$B$23 -> Reserva/Futura 04 | E22: =Configurações!$C$23 -> 0 | F22: Não verificado | G22: Não verificado | H22: Não verificado
A23: =DATE(Configurações!$B$3,1,1) -> 46023 | B23: =TEXT(A23,"ddd") -> qui | C23: =Configurações!$A$24 -> CAM 18 | D23: =Configurações!$B$24 -> Reserva/Futura 05 | E23: =Configurações!$C$24 -> 0 | F23: Não verificado | G23: Não verificado | H23: Não verificado
A24: =DATE(Configurações!$B$3,1,1) -> 46023 | B24: =TEXT(A24,"ddd") -> qui | C24: =Configurações!$A$25 -> CAM 19 | D24: =Configurações!$B$25 -> Reserva/Futura 06 | E24: =Configurações!$C$25 -> 0 | F24: Não verificado | G24: Não verificado | H24: Não verificado
A25: =DATE(Configurações!$B$3,1,1) -> 46023 | B25: =TEXT(A25,"ddd") -> qui | C25: =Configurações!$A$26 -> CAM 20 | D25: =Configurações!$B$26 -> Reserva/Futura 07 | E25: =Configurações!$C$26 -> 0 | F25: Não verificado | G25: Não verificado | H25: Não verificado
A26: =DATE(Configurações!$B$3,1,1) -> 46023 | B26: =TEXT(A26,"ddd") -> qui | C26: =Configurações!$A$27 -> CAM 21 | D26: =Configurações!$B$27 -> Reserva/Futura 08 | E26: =Configurações!$C$27 -> 0 | F26: Não verificado | G26: Não verificado | H26: Não verificado
A27: =DATE(Configurações!$B$3,1,1) -> 46023 | B27: =TEXT(A27,"ddd") -> qui | C27: =Configurações!$A$28 -> CAM 22 | D27: =Configurações!$B$28 -> Reserva/Futura 09 | E27: =Configurações!$C$28 -> 0 | F27: Não verificado | G27: Não verificado | H27: Não verificado
A28: =DATE(Configurações!$B$3,1,1) -> 46023 | B28: =TEXT(A28,"ddd") -> qui | C28: =Configurações!$A$29 -> CAM 23 | D28: =Configurações!$B$29 -> Reserva/Futura 10 | E28: =Configurações!$C$29 -> 0 | F28: Não verificado | G28: Não verificado | H28: Não verificado
A29: =DATE(Configurações!$B$3,1,2) -> 46024 | B29: =TEXT(A29,"ddd") -> sex | C29: =Configurações!$A$7 -> CAM 01 | D29: =Configurações!$B$7 -> BARU ANDES | E29: =Configurações!$C$7 -> 0 | F29: Não verificado | G29: Não verificado | H29: Não verificado
A30: =DATE(Configurações!$B$3,1,2) -> 46024 | B30: =TEXT(A30,"ddd") -> sex | C30: =Configurações!$A$8 -> CAM 02 | D30: =Configurações!$B$8 -> Câmera 02 | E30: =Configurações!$C$8 -> 0 | F30: Não verificado | G30: Não verificado | H30: Não verificado
A31: =DATE(Configurações!$B$3,1,2) -> 46024 | B31: =TEXT(A31,"ddd") -> sex | C31: =Configurações!$A$9 -> CAM 03 | D31: =Configurações!$B$9 -> Câmera 03 | E31: =Configurações!$C$9 -> 0 | F31: Não verificado | G31: Não verificado | H31: Não verificado
A32: =DATE(Configurações!$B$3,1,2) -> 46024 | B32: =TEXT(A32,"ddd") -> sex | C32: =Configurações!$A$10 -> CAM 04 | D32: =Configurações!$B$10 -> Câmera 04 | E32: =Configurações!$C$10 -> 0 | F32: Não verificado | G32: Não verificado | H32: Não verificado
A33: =DATE(Configurações!$B$3,1,2) -> 46024 | B33: =TEXT(A33,"ddd") -> sex | C33: =Configurações!$A$11 -> CAM 05 | D33: =Configurações!$B$11 -> Câmera 05 | E33: =Configurações!$C$11 -> 0 | F33: Não verificado | G33: Não verificado | H33: Não verificado
A34: =DATE(Configurações!$B$3,1,2) -> 46024 | B34: =TEXT(A34,"ddd") -> sex | C34: =Configurações!$A$12 -> CAM 06 | D34: =Configurações!$B$12 -> Câmera 06 | E34: =Configurações!$C$12 -> 0 | F34: Não verificado | G34: Não verificado | H34: Não verificado
A35: =DATE(Configurações!$B$3,1,2) -> 46024 | B35: =TEXT(A35,"ddd") -> sex | C35: =Configurações!$A$13 -> CAM 07 | D35: =Configurações!$B$13 -> Câmera 07 | E35: =Configurações!$C$13 -> 0 | F35: Não verificado | G35: Não verificado | H35: Não verificado
A36: =DATE(Configurações!$B$3,1,2) -> 46024 | B36: =TEXT(A36,"ddd") -> sex | C36: =Configurações!$A$14 -> CAM 08 | D36: =Configurações!$B$14 -> Câmera 08 | E36: =Configurações!$C$14 -> 0 | F36: Não verificado | G36: Não verificado | H36: Não verificado
A37: =DATE(Configurações!$B$3,1,2) -> 46024 | B37: =TEXT(A37,"ddd") -> sex | C37: =Configurações!$A$15 -> CAM 09 | D37: =Configurações!$B$15 -> Câmera 09 | E37: =Configurações!$C$15 -> 0 | F37: Não verificado | G37: Não verificado | H37: Não verificado
A38: =DATE(Configurações!$B$3,1,2) -> 46024 | B38: =TEXT(A38,"ddd") -> sex | C38: =Configurações!$A$16 -> CAM 10 | D38: =Configurações!$B$16 -> Câmera 10 | E38: =Configurações!$C$16 -> 0 | F38: Não verificado | G38: Não verificado | H38: Não verificado
A39: =DATE(Configurações!$B$3,1,2) -> 46024 | B39: =TEXT(A39,"ddd") -> sex | C39: =Configurações!$A$17 -> CAM 11 | D39: =Configurações!$B$17 -> Câmera 11 | E39: =Configurações!$C$17 -> 0 | F39: Não verificado | G39: Não verificado | H39: Não verificado
A40: =DATE(Configurações!$B$3,1,2) -> 46024 | B40: =TEXT(A40,"ddd") -> sex | C40: =Configurações!$A$18 -> CAM 12 | D40: =Configurações!$B$18 -> Câmera 12 | E40: =Configurações!$C$18 -> 0 | F40: Não verificado | G40: Não verificado | H40: Não verificado
A41: =DATE(Configurações!$B$3,1,2) -> 46024 | B41: =TEXT(A41,"ddd") -> sex | C41: =Configurações!$A$19 -> CAM 13 | D41: =Configurações!$B$19 -> Câmera 13 | E41: =Configurações!$C$19 -> 0 | F41: Não verificado | G41: Não verificado | H41: Não verificado
...

Sheet Fevereiro
A1: CONTROLE DE MONITORAMENTO DE CÂMERAS - FEVEREIRO
A2: Status por horário: Online / Offline / Manutenção / Não verificado. Campo livre para evento técnico e comportamento do colaborador.
M4: RESUMO DO MÊS
A5: Data | B5: Dia | C5: ID | D5: Nome da Câmera | E5: Embarcação/Local | F5: 10:00 | G5: 13:00 | H5: 16:00 | I5: Evento Técnico Online/Offline | J5: Comportamento do Colaborador | K5: Responsável | M5: Indicador | N5: Total | O5: % | P5: Meta | Q5: Observação
A6: =DATE(Configurações!$B$3,2,1) -> 46054 | B6: =TEXT(A6,"ddd") -> dom | C6: =Configurações!$A$7 -> CAM 01 | D6: =Configurações!$B$7 -> BARU ANDES | E6: =Configurações!$C$7 -> 0 | F6: Não verificado | G6: Não verificado | H6: Não verificado | M6: Online | N6: =COUNTIF(F6:H718,"Online") -> 0 | O6: =IFERROR(N6/(N6+N7+N8),0) -> 0 | P6: >=95%
A7: =DATE(Configurações!$B$3,2,1) -> 46054 | B7: =TEXT(A7,"ddd") -> dom | C7: =Configurações!$A$8 -> CAM 02 | D7: =Configurações!$B$8 -> Câmera 02 | E7: =Configurações!$C$8 -> 0 | F7: Não verificado | G7: Não verificado | H7: Não verificado | M7: Offline | N7: =COUNTIF(F6:H718,"Offline") -> 0 | O7: =IFERROR(N7/(N6+N7+N8),0) -> 0 | P7: <=5%
A8: =DATE(Configurações!$B$3,2,1) -> 46054 | B8: =TEXT(A8,"ddd") -> dom | C8: =Configurações!$A$9 -> CAM 03 | D8: =Configurações!$B$9 -> Câmera 03 | E8: =Configurações!$C$9 -> 0 | F8: Não verificado | G8: Não verificado | H8: Não verificado | M8: Manutenção | N8: =COUNTIF(F6:H718,"Manutenção") -> 0 | O8: =IFERROR(N8/(N6+N7+N8),0) -> 0
A9: =DATE(Configurações!$B$3,2,1) -> 46054 | B9: =TEXT(A9,"ddd") -> dom | C9: =Configurações!$A$10 -> CAM 04 | D9: =Configurações!$B$10 -> Câmera 04 | E9: =Configurações!$C$10 -> 0 | F9: Não verificado | G9: Não verificado | H9: Não verificado | M9: Não verificado | N9: =COUNTIF(F6:H718,"Não verificado") -> 2139 | O9: =IFERROR(N9/(N6+N7+N8+N9),0) -> 1 | P9: zerar no fechamento
A10: =DATE(Configurações!$B$3,2,1) -> 46054 | B10: =TEXT(A10,"ddd") -> dom | C10: =Configurações!$A$11 -> CAM 05 | D10: =Configurações!$B$11 -> Câmera 05 | E10: =Configurações!$C$11 -> 0 | F10: Não verificado | G10: Não verificado | H10: Não verificado | M10: Eventos registrados | N10: =COUNTA(I6:J718) -> 0
A11: =DATE(Configurações!$B$3,2,1) -> 46054 | B11: =TEXT(A11,"ddd") -> dom | C11: =Configurações!$A$12 -> CAM 06 | D11: =Configurações!$B$12 -> Câmera 06 | E11: =Configurações!$C$12 -> 0 | F11: Não verificado | G11: Não verificado | H11: Não verificado
A12: =DATE(Configurações!$B$3,2,1) -> 46054 | B12: =TEXT(A12,"ddd") -> dom | C12: =Configurações!$A$13 -> CAM 07 | D12: =Configurações!$B$13 -> Câmera 07 | E12: =Configurações!$C$13 -> 0 | F12: Não verificado | G12: Não verificado | H12: Não verificado
A13: =DATE(Configurações!$B$3,2,1) -> 46054 | B13: =TEXT(A13,"ddd") -> dom | C13: =Configurações!$A$14 -> CAM 08 | D13: =Configurações!$B$14 -> Câmera 08 | E13: =Configurações!$C$14 -> 0 | F13: Não verificado | G13: Não verificado | H13: Não verificado
A14: =DATE(Configurações!$B$3,2,1) -> 46054 | B14: =TEXT(A14,"ddd") -> dom | C14: =Configurações!$A$15 -> CAM 09 | D14: =Configurações!$B$15 -> Câmera 09 | E14: =Configurações!$C$15 -> 0 | F14: Não verificado | G14: Não verificado | H14: Não verificado
A15: =DATE(Configurações!$B$3,2,1) -> 46054 | B15: =TEXT(A15,"ddd") -> dom | C15: =Configurações!$A$16 -> CAM 10 | D15: =Configurações!$B$16 -> Câmera 10 | E15: =Configurações!$C$16 -> 0 | F15: Não verificado | G15: Não verificado | H15: Não verificado
A16: =DATE(Configurações!$B$3,2,1) -> 46054 | B16: =TEXT(A16,"ddd") -> dom | C16: =Configurações!$A$17 -> CAM 11 | D16: =Configurações!$B$17 -> Câmera 11 | E16: =Configurações!$C$17 -> 0 | F16: Não verificado | G16: Não verificado | H16: Não verificado
A17: =DATE(Configurações!$B$3,2,1) -> 46054 | B17: =TEXT(A17,"ddd") -> dom | C17: =Configurações!$A$18 -> CAM 12 | D17: =Configurações!$B$18 -> Câmera 12 | E17: =Configurações!$C$18 -> 0 | F17: Não verificado | G17: Não verificado | H17: Não verificado
A18: =DATE(Configurações!$B$3,2,1) -> 46054 | B18: =TEXT(A18,"ddd") -> dom | C18: =Configurações!$A$19 -> CAM 13 | D18: =Configurações!$B$19 -> Câmera 13 | E18: =Configurações!$C$19 -> 0 | F18: Não verificado | G18: Não verificado | H18: Não verificado
A19: =DATE(Configurações!$B$3,2,1) -> 46054 | B19: =TEXT(A19,"ddd") -> dom | C19: =Configurações!$A$20 -> CAM 14 | D19: =Configurações!$B$20 -> Reserva/Futura 01 | E19: =Configurações!$C$20 -> 0 | F19: Não verificado | G19: Não verificado | H19: Não verificado
A20: =DATE(Configurações!$B$3,2,1) -> 46054 | B20: =TEXT(A20,"ddd") -> dom | C20: =Configurações!$A$21 -> CAM 15 | D20: =Configurações!$B$21 -> Reserva/Futura 02 | E20: =Configurações!$C$21 -> 0 | F20: Não verificado | G20: Não verificado | H20: Não verificado
A21: =DATE(Configurações!$B$3,2,1) -> 46054 | B21: =TEXT(A21,"ddd") -> dom | C21: =Configurações!$A$22 -> CAM 16 | D21: =Configurações!$B$22 -> Reserva/Futura 03 | E21: =Configurações!$C$22 -> 0 | F21: Não verificado | G21: Não verificado | H21: Não verificado
A22: =DATE(Configurações!$B$3,2,1) -> 46054 | B22: =TEXT(A22,"ddd") -> dom | C22: =Configurações!$A$23 -> CAM 17 | D22: =Configurações!$B$23 -> Reserva/Futura 04 | E22: =Configurações!$C$23 -> 0 | F22: Não verificado | G22: Não verificado | H22: Não verificado
A23: =DATE(Configurações!$B$3,2,1) -> 46054 | B23: =TEXT(A23,"ddd") -> dom | C23: =Configurações!$A$24 -> CAM 18 | D23: =Configurações!$B$24 -> Reserva/Futura 05 | E23: =Configurações!$C$24 -> 0 | F23: Não verificado | G23: Não verificado | H23: Não verificado
A24: =DATE(Configurações!$B$3,2,1) -> 46054 | B24: =TEXT(A24,"ddd") -> dom | C24: =Configurações!$A$25 -> CAM 19 | D24: =Configurações!$B$25 -> Reserva/Futura 06 | E24: =Configurações!$C$25 -> 0 | F24: Não verificado | G24: Não verificado | H24: Não verificado
A25: =DATE(Configurações!$B$3,2,1) -> 46054 | B25: =TEXT(A25,"ddd") -> dom | C25: =Configurações!$A$26 -> CAM 20 | D25: =Configurações!$B$26 -> Reserva/Futura 07 | E25: =Configurações!$C$26 -> 0 | F25: Não verificado | G25: Não verificado | H25: Não verificado
A26: =DATE(Configurações!$B$3,2,1) -> 46054 | B26: =TEXT(A26,"ddd") -> dom | C26: =Configurações!$A$27 -> CAM 21 | D26: =Configurações!$B$27 -> Reserva/Futura 08 | E26: =Configurações!$C$27 -> 0 | F26: Não verificado | G26: Não verificado | H26: Não verificado
A27: =DATE(Configurações!$B$3,2,1) -> 46054 | B27: =TEXT(A27,"ddd") -> dom | C27: =Configurações!$A$28 -> CAM 22 | D27: =Configurações!$B$28 -> Reserva/Futura 09 | E27: =Configurações!$C$28 -> 0 | F27: Não verificado | G27: Não verificado | H27: Não verificado
A28: =DATE(Configurações!$B$3,2,1) -> 46054 | B28: =TEXT(A28,"ddd") -> dom | C28: =Configurações!$A$29 -> CAM 23 | D28: =Configurações!$B$29 -> Reserva/Futura 10 | E28: =Configurações!$C$29 -> 0 | F28: Não verificado | G28: Não verificado | H28: Não verificado
A29: =DATE(Configurações!$B$3,2,2) -> 46055 | B29: =TEXT(A29,"ddd") -> seg | C29: =Configurações!$A$7 -> CAM 01 | D29: =Configurações!$B$7 -> BARU ANDES | E29: =Configurações!$C$7 -> 0 | F29: Não verificado | G29: Não verificado | H29: Não verificado
A30: =DATE(Configurações!$B$3,2,2) -> 46055 | B30: =TEXT(A30,"ddd") -> seg | C30: =Configurações!$A$8 -> CAM 02 | D30: =Configurações!$B$8 -> Câmera 02 | E30: =Configurações!$C$8 -> 0 | F30: Não verificado | G30: Não verificado | H30: Não verificado
A31: =DATE(Configurações!$B$3,2,2) -> 46055 | B31: =TEXT(A31,"ddd") -> seg | C31: =Configurações!$A$9 -> CAM 03 | D31: =Configurações!$B$9 -> Câmera 03 | E31: =Configurações!$C$9 -> 0 | F31: Não verificado | G31: Não verificado | H31: Não verificado
A32: =DATE(Configurações!$B$3,2,2) -> 46055 | B32: =TEXT(A32,"ddd") -> seg | C32: =Configurações!$A$10 -> CAM 04 | D32: =Configurações!$B$10 -> Câmera 04 | E32: =Configurações!$C$10 -> 0 | F32: Não verificado | G32: Não verificado | H32: Não verificado
A33: =DATE(Configurações!$B$3,2,2) -> 46055 | B33: =TEXT(A33,"ddd") -> seg | C33: =Configurações!$A$11 -> CAM 05 | D33: =Configurações!$B$11 -> Câmera 05 | E33: =Configurações!$C$11 -> 0 | F33: Não verificado | G33: Não verificado | H33: Não verificado
A34: =DATE(Configurações!$B$3,2,2) -> 46055 | B34: =TEXT(A34,"ddd") -> seg | C34: =Configurações!$A$12 -> CAM 06 | D34: =Configurações!$B$12 -> Câmera 06 | E34: =Configurações!$C$12 -> 0 | F34: Não verificado | G34: Não verificado | H34: Não verificado
A35: =DATE(Configurações!$B$3,2,2) -> 46055 | B35: =TEXT(A35,"ddd") -> seg | C35: =Configurações!$A$13 -> CAM 07 | D35: =Configurações!$B$13 -> Câmera 07 | E35: =Configurações!$C$13 -> 0 | F35: Não verificado | G35: Não verificado | H35: Não verificado
A36: =DATE(Configurações!$B$3,2,2) -> 46055 | B36: =TEXT(A36,"ddd") -> seg | C36: =Configurações!$A$14 -> CAM 08 | D36: =Configurações!$B$14 -> Câmera 08 | E36: =Configurações!$C$14 -> 0 | F36: Não verificado | G36: Não verificado | H36: Não verificado
A37: =DATE(Configurações!$B$3,2,2) -> 46055 | B37: =TEXT(A37,"ddd") -> seg | C37: =Configurações!$A$15 -> CAM 09 | D37: =Configurações!$B$15 -> Câmera 09 | E37: =Configurações!$C$15 -> 0 | F37: Não verificado | G37: Não verificado | H37: Não verificado
A38: =DATE(Configurações!$B$3,2,2) -> 46055 | B38: =TEXT(A38,"ddd") -> seg | C38: =Configurações!$A$16 -> CAM 10 | D38: =Configurações!$B$16 -> Câmera 10 | E38: =Configurações!$C$16 -> 0 | F38: Não verificado | G38: Não verificado | H38: Não verificado
A39: =DATE(Configurações!$B$3,2,2) -> 46055 | B39: =TEXT(A39,"ddd") -> seg | C39: =Configurações!$A$17 -> CAM 11 | D39: =Configurações!$B$17 -> Câmera 11 | E39: =Configurações!$C$17 -> 0 | F39: Não verificado | G39: Não verificado | H39: Não verificado
A40: =DATE(Configurações!$B$3,2,2) -> 46055 | B40: =TEXT(A40,"ddd") -> seg | C40: =Configurações!$A$18 -> CAM 12 | D40: =Configurações!$B$18 -> Câmera 12 | E40: =Configurações!$C$18 -> 0 | F40: Não verificado | G40: Não verificado | H40: Não verificado
A41: =DATE(Configurações!$B$3,2,2) -> 46055 | B41: =TEXT(A41,"ddd") -> seg | C41: =Configurações!$A$19 -> CAM 13 | D41: =Configurações!$B$19 -> Câmera 13 | E41: =Configurações!$C$19 -> 0 | F41: Não verificado | G41: Não verificado | H41: Não verificado
...

Sheet Março
A1: CONTROLE DE MONITORAMENTO DE CÂMERAS - MARÇO
A2: Status por horário: Online / Offline / Manutenção / Não verificado. Campo livre para evento técnico e comportamento do colaborador.
M4: RESUMO DO MÊS
A5: Data | B5: Dia | C5: ID | D5: Nome da Câmera | E5: Embarcação/Local | F5: 10:00 | G5: 13:00 | H5: 16:00 | I5: Evento Técnico Online/Offline | J5: Comportamento do Colaborador | K5: Responsável | M5: Indicador | N5: Total | O5: % | P5: Meta | Q5: Observação
A6: =DATE(Configurações!$B$3,3,1) -> 46082 | B6: =TEXT(A6,"ddd") -> dom | C6: =Configurações!$A$7 -> CAM 01 | D6: =Configurações!$B$7 -> BARU ANDES | E6: =Configurações!$C$7 -> 0 | F6: Não verificado | G6: Não verificado | H6: Não verificado | M6: Online | N6: =COUNTIF(F6:H718,"Online") -> 0 | O6: =IFERROR(N6/(N6+N7+N8),0) -> 0 | P6: >=95%
A7: =DATE(Configurações!$B$3,3,1) -> 46082 | B7: =TEXT(A7,"ddd") -> dom | C7: =Configurações!$A$8 -> CAM 02 | D7: =Configurações!$B$8 -> Câmera 02 | E7: =Configurações!$C$8 -> 0 | F7: Não verificado | G7: Não verificado | H7: Não verificado | M7: Offline | N7: =COUNTIF(F6:H718,"Offline") -> 0 | O7: =IFERROR(N7/(N6+N7+N8),0) -> 0 | P7: <=5%
A8: =DATE(Configurações!$B$3,3,1) -> 46082 | B8: =TEXT(A8,"ddd") -> dom | C8: =Configurações!$A$9 -> CAM 03 | D8: =Configurações!$B$9 -> Câmera 03 | E8: =Configurações!$C$9 -> 0 | F8: Não verificado | G8: Não verificado | H8: Não verificado | M8: Manutenção | N8: =COUNTIF(F6:H718,"Manutenção") -> 0 | O8: =IFERROR(N8/(N6+N7+N8),0) -> 0
A9: =DATE(Configurações!$B$3,3,1) -> 46082 | B9: =TEXT(A9,"ddd") -> dom | C9: =Configurações!$A$10 -> CAM 04 | D9: =Configurações!$B$10 -> Câmera 04 | E9: =Configurações!$C$10 -> 0 | F9: Não verificado | G9: Não verificado | H9: Não verificado | M9: Não verificado | N9: =COUNTIF(F6:H718,"Não verificado") -> 2139 | O9: =IFERROR(N9/(N6+N7+N8+N9),0) -> 1 | P9: zerar no fechamento
A10: =DATE(Configurações!$B$3,3,1) -> 46082 | B10: =TEXT(A10,"ddd") -> dom | C10: =Configurações!$A$11 -> CAM 05 | D10: =Configurações!$B$11 -> Câmera 05 | E10: =Configurações!$C$11 -> 0 | F10: Não verificado | G10: Não verificado | H10: Não verificado | M10: Eventos registrados | N10: =COUNTA(I6:J718) -> 0
A11: =DATE(Configurações!$B$3,3,1) -> 46082 | B11: =TEXT(A11,"ddd") -> dom | C11: =Configurações!$A$12 -> CAM 06 | D11: =Configurações!$B$12 -> Câmera 06 | E11: =Configurações!$C$12 -> 0 | F11: Não verificado | G11: Não verificado | H11: Não verificado
A12: =DATE(Configurações!$B$3,3,1) -> 46082 | B12: =TEXT(A12,"ddd") -> dom | C12: =Configurações!$A$13 -> CAM 07 | D12: =Configurações!$B$13 -> Câmera 07 | E12: =Configurações!$C$13 -> 0 | F12: Não verificado | G12: Não verificado | H12: Não verificado
A13: =DATE(Configurações!$B$3,3,1) -> 46082 | B13: =TEXT(A13,"ddd") -> dom | C13: =Configurações!$A$14 -> CAM 08 | D13: =Configurações!$B$14 -> Câmera 08 | E13: =Configurações!$C$14 -> 0 | F13: Não verificado | G13: Não verificado | H13: Não verificado
A14: =DATE(Configurações!$B$3,3,1) -> 46082 | B14: =TEXT(A14,"ddd") -> dom | C14: =Configurações!$A$15 -> CAM 09 | D14: =Configurações!$B$15 -> Câmera 09 | E14: =Configurações!$C$15 -> 0 | F14: Não verificado | G14: Não verificado | H14: Não verificado
A15: =DATE(Configurações!$B$3,3,1) -> 46082 | B15: =TEXT(A15,"ddd") -> dom | C15: =Configurações!$A$16 -> CAM 10 | D15: =Configurações!$B$16 -> Câmera 10 | E15: =Configurações!$C$16 -> 0 | F15: Não verificado | G15: Não verificado | H15: Não verificado
A16: =DATE(Configurações!$B$3,3,1) -> 46082 | B16: =TEXT(A16,"ddd") -> dom | C16: =Configurações!$A$17 -> CAM 11 | D16: =Configurações!$B$17 -> Câmera 11 | E16: =Configurações!$C$17 -> 0 | F16: Não verificado | G16: Não verificado | H16: Não verificado
A17: =DATE(Configurações!$B$3,3,1) -> 46082 | B17: =TEXT(A17,"ddd") -> dom | C17: =Configurações!$A$18 -> CAM 12 | D17: =Configurações!$B$18 -> Câmera 12 | E17: =Configurações!$C$18 -> 0 | F17: Não verificado | G17: Não verificado | H17: Não verificado
A18: =DATE(Configurações!$B$3,3,1) -> 46082 | B18: =TEXT(A18,"ddd") -> dom | C18: =Configurações!$A$19 -> CAM 13 | D18: =Configurações!$B$19 -> Câmera 13 | E18: =Configurações!$C$19 -> 0 | F18: Não verificado | G18: Não verificado | H18: Não verificado
A19: =DATE(Configurações!$B$3,3,1) -> 46082 | B19: =TEXT(A19,"ddd") -> dom | C19: =Configurações!$A$20 -> CAM 14 | D19: =Configurações!$B$20 -> Reserva/Futura 01 | E19: =Configurações!$C$20 -> 0 | F19: Não verificado | G19: Não verificado | H19: Não verificado
A20: =DATE(Configurações!$B$3,3,1) -> 46082 | B20: =TEXT(A20,"ddd") -> dom | C20: =Configurações!$A$21 -> CAM 15 | D20: =Configurações!$B$21 -> Reserva/Futura 02 | E20: =Configurações!$C$21 -> 0 | F20: Não verificado | G20: Não verificado | H20: Não verificado
A21: =DATE(Configurações!$B$3,3,1) -> 46082 | B21: =TEXT(A21,"ddd") -> dom | C21: =Configurações!$A$22 -> CAM 16 | D21: =Configurações!$B$22 -> Reserva/Futura 03 | E21: =Configurações!$C$22 -> 0 | F21: Não verificado | G21: Não verificado | H21: Não verificado
A22: =DATE(Configurações!$B$3,3,1) -> 46082 | B22: =TEXT(A22,"ddd") -> dom | C22: =Configurações!$A$23 -> CAM 17 | D22: =Configurações!$B$23 -> Reserva/Futura 04 | E22: =Configurações!$C$23 -> 0 | F22: Não verificado | G22: Não verificado | H22: Não verificado
A23: =DATE(Configurações!$B$3,3,1) -> 46082 | B23: =TEXT(A23,"ddd") -> dom | C23: =Configurações!$A$24 -> CAM 18 | D23: =Configurações!$B$24 -> Reserva/Futura 05 | E23: =Configurações!$C$24 -> 0 | F23: Não verificado | G23: Não verificado | H23: Não verificado
A24: =DATE(Configurações!$B$3,3,1) -> 46082 | B24: =TEXT(A24,"ddd") -> dom | C24: =Configurações!$A$25 -> CAM 19 | D24: =Configurações!$B$25 -> Reserva/Futura 06 | E24: =Configurações!$C$25 -> 0 | F24: Não verificado | G24: Não verificado | H24: Não verificado
A25: =DATE(Configurações!$B$3,3,1) -> 46082 | B25: =TEXT(A25,"ddd") -> dom | C25: =Configurações!$A$26 -> CAM 20 | D25: =Configurações!$B$26 -> Reserva/Futura 07 | E25: =Configurações!$C$26 -> 0 | F25: Não verificado | G25: Não verificado | H25: Não verificado
A26: =DATE(Configurações!$B$3,3,1) -> 46082 | B26: =TEXT(A26,"ddd") -> dom | C26: =Configurações!$A$27 -> CAM 21 | D26: =Configurações!$B$27 -> Reserva/Futura 08 | E26: =Configurações!$C$27 -> 0 | F26: Não verificado | G26: Não verificado | H26: Não verificado
A27: =DATE(Configurações!$B$3,3,1) -> 46082 | B27: =TEXT(A27,"ddd") -> dom | C27: =Configurações!$A$28 -> CAM 22 | D27: =Configurações!$B$28 -> Reserva/Futura 09 | E27: =Configurações!$C$28 -> 0 | F27: Não verificado | G27: Não verificado | H27: Não verificado
A28: =DATE(Configurações!$B$3,3,1) -> 46082 | B28: =TEXT(A28,"ddd") -> dom | C28: =Configurações!$A$29 -> CAM 23 | D28: =Configurações!$B$29 -> Reserva/Futura 10 | E28: =Configurações!$C$29 -> 0 | F28: Não verificado | G28: Não verificado | H28: Não verificado
A29: =DATE(Configurações!$B$3,3,2) -> 46083 | B29: =TEXT(A29,"ddd") -> seg | C29: =Configurações!$A$7 -> CAM 01 | D29: =Configurações!$B$7 -> BARU ANDES | E29: =Configurações!$C$7 -> 0 | F29: Não verificado | G29: Não verificado | H29: Não verificado
A30: =DATE(Configurações!$B$3,3,2) -> 46083 | B30: =TEXT(A30,"ddd") -> seg | C30: =Configurações!$A$8 -> CAM 02 | D30: =Configurações!$B$8 -> Câmera 02 | E30: =Configurações!$C$8 -> 0 | F30: Não verificado | G30: Não verificado | H30: Não verificado
A31: =DATE(Configurações!$B$3,3,2) -> 46083 | B31: =TEXT(A31,"ddd") -> seg | C31: =Configurações!$A$9 -> CAM 03 | D31: =Configurações!$B$9 -> Câmera 03 | E31: =Configurações!$C$9 -> 0 | F31: Não verificado | G31: Não verificado | H31: Não verificado
A32: =DATE(Configurações!$B$3,3,2) -> 46083 | B32: =TEXT(A32,"ddd") -> seg | C32: =Configurações!$A$10 -> CAM 04 | D32: =Configurações!$B$10 -> Câmera 04 | E32: =Configurações!$C$10 -> 0 | F32: Não verificado | G32: Não verificado | H32: Não verificado
A33: =DATE(Configurações!$B$3,3,2) -> 46083 | B33: =TEXT(A33,"ddd") -> seg | C33: =Configurações!$A$11 -> CAM 05 | D33: =Configurações!$B$11 -> Câmera 05 | E33: =Configurações!$C$11 -> 0 | F33: Não verificado | G33: Não verificado | H33: Não verificado
A34: =DATE(Configurações!$B$3,3,2) -> 46083 | B34: =TEXT(A34,"ddd") -> seg | C34: =Configurações!$A$12 -> CAM 06 | D34: =Configurações!$B$12 -> Câmera 06 | E34: =Configurações!$C$12 -> 0 | F34: Não verificado | G34: Não verificado | H34: Não verificado
A35: =DATE(Configurações!$B$3,3,2) -> 46083 | B35: =TEXT(A35,"ddd") -> seg | C35: =Configurações!$A$13 -> CAM 07 | D35: =Configurações!$B$13 -> Câmera 07 | E35: =Configurações!$C$13 -> 0 | F35: Não verificado | G35: Não verificado | H35: Não verificado
A36: =DATE(Configurações!$B$3,3,2) -> 46083 | B36: =TEXT(A36,"ddd") -> seg | C36: =Configurações!$A$14 -> CAM 08 | D36: =Configurações!$B$14 -> Câmera 08 | E36: =Configurações!$C$14 -> 0 | F36: Não verificado | G36: Não verificado | H36: Não verificado
A37: =DATE(Configurações!$B$3,3,2) -> 46083 | B37: =TEXT(A37,"ddd") -> seg | C37: =Configurações!$A$15 -> CAM 09 | D37: =Configurações!$B$15 -> Câmera 09 | E37: =Configurações!$C$15 -> 0 | F37: Não verificado | G37: Não verificado | H37: Não verificado
A38: =DATE(Configurações!$B$3,3,2) -> 46083 | B38: =TEXT(A38,"ddd") -> seg | C38: =Configurações!$A$16 -> CAM 10 | D38: =Configurações!$B$16 -> Câmera 10 | E38: =Configurações!$C$16 -> 0 | F38: Não verificado | G38: Não verificado | H38: Não verificado
A39: =DATE(Configurações!$B$3,3,2) -> 46083 | B39: =TEXT(A39,"ddd") -> seg | C39: =Configurações!$A$17 -> CAM 11 | D39: =Configurações!$B$17 -> Câmera 11 | E39: =Configurações!$C$17 -> 0 | F39: Não verificado | G39: Não verificado | H39: Não verificado
A40: =DATE(Configurações!$B$3,3,2) -> 46083 | B40: =TEXT(A40,"ddd") -> seg | C40: =Configurações!$A$18 -> CAM 12 | D40: =Configurações!$B$18 -> Câmera 12 | E40: =Configurações!$C$18 -> 0 | F40: Não verificado | G40: Não verificado | H40: Não verificado
A41: =DATE(Configurações!$B$3,3,2) -> 46083 | B41: =TEXT(A41,"ddd") -> seg | C41: =Configurações!$A$19 -> CAM 13 | D41: =Configurações!$B$19 -> Câmera 13 | E41: =Configurações!$C$19 -> 0 | F41: Não verificado | G41: Não verificado | H41: Não verificado
...

Sheet Abril
A1: CONTROLE DE MONITORAMENTO DE CÂMERAS - ABRIL
A2: Status por horário: Online / Offline / Manutenção / Não verificado. Campo livre para evento técnico e comportamento do colaborador.
M4: RESUMO DO MÊS
A5: Data | B5: Dia | C5: ID | D5: Nome da Câmera | E5: Embarcação/Local | F5: 10:00 | G5: 13:00 | H5: 16:00 | I5: Evento Técnico Online/Offline | J5: Comportamento do Colaborador | K5: Responsável | M5: Indicador | N5: Total | O5: % | P5: Meta | Q5: Observação
A6: =DATE(Configurações!$B$3,4,1) -> 46113 | B6: =TEXT(A6,"ddd") -> qua | C6: =Configurações!$A$7 -> CAM 01 | D6: =Configurações!$B$7 -> BARU ANDES | E6: =Configurações!$C$7 -> 0 | F6: Não verificado | G6: Não verificado | H6: Não verificado | M6: Online | N6: =COUNTIF(F6:H718,"Online") -> 0 | O6: =IFERROR(N6/(N6+N7+N8),0) -> 0 | P6: >=95%
A7: =DATE(Configurações!$B$3,4,1) -> 46113 | B7: =TEXT(A7,"ddd") -> qua | C7: =Configurações!$A$8 -> CAM 02 | D7: =Configurações!$B$8 -> Câmera 02 | E7: =Configurações!$C$8 -> 0 | F7: Não verificado | G7: Não verificado | H7: Não verificado | M7: Offline | N7: =COUNTIF(F6:H718,"Offline") -> 0 | O7: =IFERROR(N7/(N6+N7+N8),0) -> 0 | P7: <=5%
A8: =DATE(Configurações!$B$3,4,1) -> 46113 | B8: =TEXT(A8,"ddd") -> qua | C8: =Configurações!$A$9 -> CAM 03 | D8: =Configurações!$B$9 -> Câmera 03 | E8: =Configurações!$C$9 -> 0 | F8: Não verificado | G8: Não verificado | H8: Não verificado | M8: Manutenção | N8: =COUNTIF(F6:H718,"Manutenção") -> 0 | O8: =IFERROR(N8/(N6+N7+N8),0) -> 0
A9: =DATE(Configurações!$B$3,4,1) -> 46113 | B9: =TEXT(A9,"ddd") -> qua | C9: =Configurações!$A$10 -> CAM 04 | D9: =Configurações!$B$10 -> Câmera 04 | E9: =Configurações!$C$10 -> 0 | F9: Não verificado | G9: Não verificado | H9: Não verificado | M9: Não verificado | N9: =COUNTIF(F6:H718,"Não verificado") -> 2139 | O9: =IFERROR(N9/(N6+N7+N8+N9),0) -> 1 | P9: zerar no fechamento
A10: =DATE(Configurações!$B$3,4,1) -> 46113 | B10: =TEXT(A10,"ddd") -> qua | C10: =Configurações!$A$11 -> CAM 05 | D10: =Configurações!$B$11 -> Câmera 05 | E10: =Configurações!$C$11 -> 0 | F10: Não verificado | G10: Não verificado | H10: Não verificado | M10: Eventos registrados | N10: =COUNTA(I6:J718) -> 0
A11: =DATE(Configurações!$B$3,4,1) -> 46113 | B11: =TEXT(A11,"ddd") -> qua | C11: =Configurações!$A$12 -> CAM 06 | D11: =Configurações!$B$12 -> Câmera 06 | E11: =Configurações!$C$12 -> 0 | F11: Não verificado | G11: Não verificado | H11: Não verificado
A12: =DATE(Configurações!$B$3,4,1) -> 46113 | B12: =TEXT(A12,"ddd") -> qua | C12: =Configurações!$A$13 -> CAM 07 | D12: =Configurações!$B$13 -> Câmera 07 | E12: =Configurações!$C$13 -> 0 | F12: Não verificado | G12: Não verificado | H12: Não verificado
A13: =DATE(Configurações!$B$3,4,1) -> 46113 | B13: =TEXT(A13,"ddd") -> qua | C13: =Configurações!$A$14 -> CAM 08 | D13: =Configurações!$B$14 -> Câmera 08 | E13: =Configurações!$C$14 -> 0 | F13: Não verificado | G13: Não verificado | H13: Não verificado
A14: =DATE(Configurações!$B$3,4,1) -> 46113 | B14: =TEXT(A14,"ddd") -> qua | C14: =Configurações!$A$15 -> CAM 09 | D14: =Configurações!$B$15 -> Câmera 09 | E14: =Configurações!$C$15 -> 0 | F14: Não verificado | G14: Não verificado | H14: Não verificado
A15: =DATE(Configurações!$B$3,4,1) -> 46113 | B15: =TEXT(A15,"ddd") -> qua | C15: =Configurações!$A$16 -> CAM 10 | D15: =Configurações!$B$16 -> Câmera 10 | E15: =Configurações!$C$16 -> 0 | F15: Não verificado | G15: Não verificado | H15: Não verificado
A16: =DATE(Configurações!$B$3,4,1) -> 46113 | B16: =TEXT(A16,"ddd") -> qua | C16: =Configurações!$A$17 -> CAM 11 | D16: =Configurações!$B$17 -> Câmera 11 | E16: =Configurações!$C$17 -> 0 | F16: Não verificado | G16: Não verificado | H16: Não verificado
A17: =DATE(Configurações!$B$3,4,1) -> 46113 | B17: =TEXT(A17,"ddd") -> qua | C17: =Configurações!$A$18 -> CAM 12 | D17: =Configurações!$B$18 -> Câmera 12 | E17: =Configurações!$C$18 -> 0 | F17: Não verificado | G17: Não verificado | H17: Não verificado
A18: =DATE(Configurações!$B$3,4,1) -> 46113 | B18: =TEXT(A18,"ddd") -> qua | C18: =Configurações!$A$19 -> CAM 13 | D18: =Configurações!$B$19 -> Câmera 13 | E18: =Configurações!$C$19 -> 0 | F18: Não verificado | G18: Não verificado | H18: Não verificado
A19: =DATE(Configurações!$B$3,4,1) -> 46113 | B19: =TEXT(A19,"ddd") -> qua | C19: =Configurações!$A$20 -> CAM 14 | D19: =Configurações!$B$20 -> Reserva/Futura 01 | E19: =Configurações!$C$20 -> 0 | F19: Não verificado | G19: Não verificado | H19: Não verificado
A20: =DATE(Configurações!$B$3,4,1) -> 46113 | B20: =TEXT(A20,"ddd") -> qua | C20: =Configurações!$A$21 -> CAM 15 | D20: =Configurações!$B$21 -> Reserva/Futura 02 | E20: =Configurações!$C$21 -> 0 | F20: Não verificado | G20: Não verificado | H20: Não verificado
A21: =DATE(Configurações!$B$3,4,1) -> 46113 | B21: =TEXT(A21,"ddd") -> qua | C21: =Configurações!$A$22 -> CAM 16 | D21: =Configurações!$B$22 -> Reserva/Futura 03 | E21: =Configurações!$C$22 -> 0 | F21: Não verificado | G21: Não verificado | H21: Não verificado
A22: =DATE(Configurações!$B$3,4,1) -> 46113 | B22: =TEXT(A22,"ddd") -> qua | C22: =Configurações!$A$23 -> CAM 17 | D22: =Configurações!$B$23 -> Reserva/Futura 04 | E22: =Configurações!$C$23 -> 0 | F22: Não verificado | G22: Não verificado | H22: Não verificado
A23: =DATE(Configurações!$B$3,4,1) -> 46113 | B23: =TEXT(A23,"ddd") -> qua | C23: =Configurações!$A$24 -> CAM 18 | D23: =Configurações!$B$24 -> Reserva/Futura 05 | E23: =Configurações!$C$24 -> 0 | F23: Não verificado | G23: Não verificado | H23: Não verificado
A24: =DATE(Configurações!$B$3,4,1) -> 46113 | B24: =TEXT(A24,"ddd") -> qua | C24: =Configurações!$A$25 -> CAM 19 | D24: =Configurações!$B$25 -> Reserva/Futura 06 | E24: =Configurações!$C$25 -> 0 | F24: Não verificado | G24: Não verificado | H24: Não verificado
A25: =DATE(Configurações!$B$3,4,1) -> 46113 | B25: =TEXT(A25,"ddd") -> qua | C25: =Configurações!$A$26 -> CAM 20 | D25: =Configurações!$B$26 -> Reserva/Futura 07 | E25: =Configurações!$C$26 -> 0 | F25: Não verificado | G25: Não verificado | H25: Não verificado
A26: =DATE(Configurações!$B$3,4,1) -> 46113 | B26: =TEXT(A26,"ddd") -> qua | C26: =Configurações!$A$27 -> CAM 21 | D26: =Configurações!$B$27 -> Reserva/Futura 08 | E26: =Configurações!$C$27 -> 0 | F26: Não verificado | G26: Não verificado | H26: Não verificado
A27: =DATE(Configurações!$B$3,4,1) -> 46113 | B27: =TEXT(A27,"ddd") -> qua | C27: =Configurações!$A$28 -> CAM 22 | D27: =Configurações!$B$28 -> Reserva/Futura 09 | E27: =Configurações!$C$28 -> 0 | F27: Não verificado | G27: Não verificado | H27: Não verificado
A28: =DATE(Configurações!$B$3,4,1) -> 46113 | B28: =TEXT(A28,"ddd") -> qua | C28: =Configurações!$A$29 -> CAM 23 | D28: =Configurações!$B$29 -> Reserva/Futura 10 | E28: =Configurações!$C$29 -> 0 | F28: Não verificado | G28: Não verificado | H28: Não verificado
A29: =DATE(Configurações!$B$3,4,2) -> 46114 | B29: =TEXT(A29,"ddd") -> qui | C29: =Configurações!$A$7 -> CAM 01 | D29: =Configurações!$B$7 -> BARU ANDES | E29: =Configurações!$C$7 -> 0 | F29: Não verificado | G29: Não verificado | H29: Não verificado
A30: =DATE(Configurações!$B$3,4,2) -> 46114 | B30: =TEXT(A30,"ddd") -> qui | C30: =Configurações!$A$8 -> CAM 02 | D30: =Configurações!$B$8 -> Câmera 02 | E30: =Configurações!$C$8 -> 0 | F30: Não verificado | G30: Não verificado | H30: Não verificado
A31: =DATE(Configurações!$B$3,4,2) -> 46114 | B31: =TEXT(A31,"ddd") -> qui | C31: =Configurações!$A$9 -> CAM 03 | D31: =Configurações!$B$9 -> Câmera 03 | E31: =Configurações!$C$9 -> 0 | F31: Não verificado | G31: Não verificado | H31: Não verificado
A32: =DATE(Configurações!$B$3,4,2) -> 46114 | B32: =TEXT(A32,"ddd") -> qui | C32: =Configurações!$A$10 -> CAM 04 | D32: =Configurações!$B$10 -> Câmera 04 | E32: =Configurações!$C$10 -> 0 | F32: Não verificado | G32: Não verificado | H32: Não verificado
A33: =DATE(Configurações!$B$3,4,2) -> 46114 | B33: =TEXT(A33,"ddd") -> qui | C33: =Configurações!$A$11 -> CAM 05 | D33: =Configurações!$B$11 -> Câmera 05 | E33: =Configurações!$C$11 -> 0 | F33: Não verificado | G33: Não verificado | H33: Não verificado
A34: =DATE(Configurações!$B$3,4,2) -> 46114 | B34: =TEXT(A34,"ddd") -> qui | C34: =Configurações!$A$12 -> CAM 06 | D34: =Configurações!$B$12 -> Câmera 06 | E34: =Configurações!$C$12 -> 0 | F34: Não verificado | G34: Não verificado | H34: Não verificado
A35: =DATE(Configurações!$B$3,4,2) -> 46114 | B35: =TEXT(A35,"ddd") -> qui | C35: =Configurações!$A$13 -> CAM 07 | D35: =Configurações!$B$13 -> Câmera 07 | E35: =Configurações!$C$13 -> 0 | F35: Não verificado | G35: Não verificado | H35: Não verificado
A36: =DATE(Configurações!$B$3,4,2) -> 46114 | B36: =TEXT(A36,"ddd") -> qui | C36: =Configurações!$A$14 -> CAM 08 | D36: =Configurações!$B$14 -> Câmera 08 | E36: =Configurações!$C$14 -> 0 | F36: Não verificado | G36: Não verificado | H36: Não verificado
A37: =DATE(Configurações!$B$3,4,2) -> 46114 | B37: =TEXT(A37,"ddd") -> qui | C37: =Configurações!$A$15 -> CAM 09 | D37: =Configurações!$B$15 -> Câmera 09 | E37: =Configurações!$C$15 -> 0 | F37: Não verificado | G37: Não verificado | H37: Não verificado
A38: =DATE(Configurações!$B$3,4,2) -> 46114 | B38: =TEXT(A38,"ddd") -> qui | C38: =Configurações!$A$16 -> CAM 10 | D38: =Configurações!$B$16 -> Câmera 10 | E38: =Configurações!$C$16 -> 0 | F38: Não verificado | G38: Não verificado | H38: Não verificado
A39: =DATE(Configurações!$B$3,4,2) -> 46114 | B39: =TEXT(A39,"ddd") -> qui | C39: =Configurações!$A$17 -> CAM 11 | D39: =Configurações!$B$17 -> Câmera 11 | E39: =Configurações!$C$17 -> 0 | F39: Não verificado | G39: Não verificado | H39: Não verificado
A40: =DATE(Configurações!$B$3,4,2) -> 46114 | B40: =TEXT(A40,"ddd") -> qui | C40: =Configurações!$A$18 -> CAM 12 | D40: =Configurações!$B$18 -> Câmera 12 | E40: =Configurações!$C$18 -> 0 | F40: Não verificado | G40: Não verificado | H40: Não verificado
A41: =DATE(Configurações!$B$3,4,2) -> 46114 | B41: =TEXT(A41,"ddd") -> qui | C41: =Configurações!$A$19 -> CAM 13 | D41: =Configurações!$B$19 -> Câmera 13 | E41: =Configurações!$C$19 -> 0 | F41: Não verificado | G41: Não verificado | H41: Não verificado
...

Sheet Maio
A1: CONTROLE DE MONITORAMENTO DE CÂMERAS - MAIO
A2: Status por horário: Online / Offline / Manutenção / Não verificado. Campo livre para evento técnico e comportamento do colaborador.
M4: RESUMO DO MÊS
A5: Data | B5: Dia | C5: ID | D5: Nome da Câmera | E5: Embarcação/Local | F5: 10:00 | G5: 13:00 | H5: 16:00 | I5: Evento Técnico Online/Offline | J5: Comportamento do Colaborador | K5: Responsável | M5: Indicador | N5: Total | O5: % | P5: Meta | Q5: Observação
A6: =DATE(Configurações!$B$3,5,1) -> 46143 | B6: =TEXT(A6,"ddd") -> sex | C6: =Configurações!$A$7 -> CAM 01 | D6: =Configurações!$B$7 -> BARU ANDES | E6: =Configurações!$C$7 -> 0 | F6: Não verificado | G6: Não verificado | H6: Não verificado | M6: Online | N6: =COUNTIF(F6:H718,"Online") -> 0 | O6: =IFERROR(N6/(N6+N7+N8),0) -> 0 | P6: >=95%
A7: =DATE(Configurações!$B$3,5,1) -> 46143 | B7: =TEXT(A7,"ddd") -> sex | C7: =Configurações!$A$8 -> CAM 02 | D7: =Configurações!$B$8 -> Câmera 02 | E7: =Configurações!$C$8 -> 0 | F7: Não verificado | G7: Não verificado | H7: Não verificado | M7: Offline | N7: =COUNTIF(F6:H718,"Offline") -> 0 | O7: =IFERROR(N7/(N6+N7+N8),0) -> 0 | P7: <=5%
A8: =DATE(Configurações!$B$3,5,1) -> 46143 | B8: =TEXT(A8,"ddd") -> sex | C8: =Configurações!$A$9 -> CAM 03 | D8: =Configurações!$B$9 -> Câmera 03 | E8: =Configurações!$C$9 -> 0 | F8: Não verificado | G8: Não verificado | H8: Não verificado | M8: Manutenção | N8: =COUNTIF(F6:H718,"Manutenção") -> 0 | O8: =IFERROR(N8/(N6+N7+N8),0) -> 0
A9: =DATE(Configurações!$B$3,5,1) -> 46143 | B9: =TEXT(A9,"ddd") -> sex | C9: =Configurações!$A$10 -> CAM 04 | D9: =Configurações!$B$10 -> Câmera 04 | E9: =Configurações!$C$10 -> 0 | F9: Não verificado | G9: Não verificado | H9: Não verificado | M9: Não verificado | N9: =COUNTIF(F6:H718,"Não verificado") -> 2139 | O9: =IFERROR(N9/(N6+N7+N8+N9),0) -> 1 | P9: zerar no fechamento
A10: =DATE(Configurações!$B$3,5,1) -> 46143 | B10: =TEXT(A10,"ddd") -> sex | C10: =Configurações!$A$11 -> CAM 05 | D10: =Configurações!$B$11 -> Câmera 05 | E10: =Configurações!$C$11 -> 0 | F10: Não verificado | G10: Não verificado | H10: Não verificado | M10: Eventos registrados | N10: =COUNTA(I6:J718) -> 0
A11: =DATE(Configurações!$B$3,5,1) -> 46143 | B11: =TEXT(A11,"ddd") -> sex | C11: =Configurações!$A$12 -> CAM 06 | D11: =Configurações!$B$12 -> Câmera 06 | E11: =Configurações!$C$12 -> 0 | F11: Não verificado | G11: Não verificado | H11: Não verificado
A12: =DATE(Configurações!$B$3,5,1) -> 46143 | B12: =TEXT(A12,"ddd") -> sex | C12: =Configurações!$A$13 -> CAM 07 | D12: =Configurações!$B$13 -> Câmera 07 | E12: =Configurações!$C$13 -> 0 | F12: Não verificado | G12: Não verificado | H12: Não verificado
A13: =DATE(Configurações!$B$3,5,1) -> 46143 | B13: =TEXT(A13,"ddd") -> sex | C13: =Configurações!$A$14 -> CAM 08 | D13: =Configurações!$B$14 -> Câmera 08 | E13: =Configurações!$C$14 -> 0 | F13: Não verificado | G13: Não verificado | H13: Não verificado
A14: =DATE(Configurações!$B$3,5,1) -> 46143 | B14: =TEXT(A14,"ddd") -> sex | C14: =Configurações!$A$15 -> CAM 09 | D14: =Configurações!$B$15 -> Câmera 09 | E14: =Configurações!$C$15 -> 0 | F14: Não verificado | G14: Não verificado | H14: Não verificado
A15: =DATE(Configurações!$B$3,5,1) -> 46143 | B15: =TEXT(A15,"ddd") -> sex | C15: =Configurações!$A$16 -> CAM 10 | D15: =Configurações!$B$16 -> Câmera 10 | E15: =Configurações!$C$16 -> 0 | F15: Não verificado | G15: Não verificado | H15: Não verificado
A16: =DATE(Configurações!$B$3,5,1) -> 46143 | B16: =TEXT(A16,"ddd") -> sex | C16: =Configurações!$A$17 -> CAM 11 | D16: =Configurações!$B$17 -> Câmera 11 | E16: =Configurações!$C$17 -> 0 | F16: Não verificado | G16: Não verificado | H16: Não verificado
A17: =DATE(Configurações!$B$3,5,1) -> 46143 | B17: =TEXT(A17,"ddd") -> sex | C17: =Configurações!$A$18 -> CAM 12 | D17: =Configurações!$B$18 -> Câmera 12 | E17: =Configurações!$C$18 -> 0 | F17: Não verificado | G17: Não verificado | H17: Não verificado
A18: =DATE(Configurações!$B$3,5,1) -> 46143 | B18: =TEXT(A18,"ddd") -> sex | C18: =Configurações!$A$19 -> CAM 13 | D18: =Configurações!$B$19 -> Câmera 13 | E18: =Configurações!$C$19 -> 0 | F18: Não verificado | G18: Não verificado | H18: Não verificado
A19: =DATE(Configurações!$B$3,5,1) -> 46143 | B19: =TEXT(A19,"ddd") -> sex | C19: =Configurações!$A$20 -> CAM 14 | D19: =Configurações!$B$20 -> Reserva/Futura 01 | E19: =Configurações!$C$20 -> 0 | F19: Não verificado | G19: Não verificado | H19: Não verificado
A20: =DATE(Configurações!$B$3,5,1) -> 46143 | B20: =TEXT(A20,"ddd") -> sex | C20: =Configurações!$A$21 -> CAM 15 | D20: =Configurações!$B$21 -> Reserva/Futura 02 | E20: =Configurações!$C$21 -> 0 | F20: Não verificado | G20: Não verificado | H20: Não verificado
A21: =DATE(Configurações!$B$3,5,1) -> 46143 | B21: =TEXT(A21,"ddd") -> sex | C21: =Configurações!$A$22 -> CAM 16 | D21: =Configurações!$B$22 -> Reserva/Futura 03 | E21: =Configurações!$C$22 -> 0 | F21: Não verificado | G21: Não verificado | H21: Não verificado
A22: =DATE(Configurações!$B$3,5,1) -> 46143 | B22: =TEXT(A22,"ddd") -> sex | C22: =Configurações!$A$23 -> CAM 17 | D22: =Configurações!$B$23 -> Reserva/Futura 04 | E22: =Configurações!$C$23 -> 0 | F22: Não verificado | G22: Não verificado | H22: Não verificado
A23: =DATE(Configurações!$B$3,5,1) -> 46143 | B23: =TEXT(A23,"ddd") -> sex | C23: =Configurações!$A$24 -> CAM 18 | D23: =Configurações!$B$24 -> Reserva/Futura 05 | E23: =Configurações!$C$24 -> 0 | F23: Não verificado | G23: Não verificado | H23: Não verificado
A24: =DATE(Configurações!$B$3,5,1) -> 46143 | B24: =TEXT(A24,"ddd") -> sex | C24: =Configurações!$A$25 -> CAM 19 | D24: =Configurações!$B$25 -> Reserva/Futura 06 | E24: =Configurações!$C$25 -> 0 | F24: Não verificado | G24: Não verificado | H24: Não verificado
A25: =DATE(Configurações!$B$3,5,1) -> 46143 | B25: =TEXT(A25,"ddd") -> sex | C25: =Configurações!$A$26 -> CAM 20 | D25: =Configurações!$B$26 -> Reserva/Futura 07 | E25: =Configurações!$C$26 -> 0 | F25: Não verificado | G25: Não verificado | H25: Não verificado
A26: =DATE(Configurações!$B$3,5,1) -> 46143 | B26: =TEXT(A26,"ddd") -> sex | C26: =Configurações!$A$27 -> CAM 21 | D26: =Configurações!$B$27 -> Reserva/Futura 08 | E26: =Configurações!$C$27 -> 0 | F26: Não verificado | G26: Não verificado | H26: Não verificado
A27: =DATE(Configurações!$B$3,5,1) -> 46143 | B27: =TEXT(A27,"ddd") -> sex | C27: =Configurações!$A$28 -> CAM 22 | D27: =Configurações!$B$28 -> Reserva/Futura 09 | E27: =Configurações!$C$28 -> 0 | F27: Não verificado | G27: Não verificado | H27: Não verificado
A28: =DATE(Configurações!$B$3,5,1) -> 46143 | B28: =TEXT(A28,"ddd") -> sex | C28: =Configurações!$A$29 -> CAM 23 | D28: =Configurações!$B$29 -> Reserva/Futura 10 | E28: =Configurações!$C$29 -> 0 | F28: Não verificado | G28: Não verificado | H28: Não verificado
A29: =DATE(Configurações!$B$3,5,2) -> 46144 | B29: =TEXT(A29,"ddd") -> sáb | C29: =Configurações!$A$7 -> CAM 01 | D29: =Configurações!$B$7 -> BARU ANDES | E29: =Configurações!$C$7 -> 0 | F29: Não verificado | G29: Não verificado | H29: Não verificado
A30: =DATE(Configurações!$B$3,5,2) -> 46144 | B30: =TEXT(A30,"ddd") -> sáb | C30: =Configurações!$A$8 -> CAM 02 | D30: =Configurações!$B$8 -> Câmera 02 | E30: =Configurações!$C$8 -> 0 | F30: Não verificado | G30: Não verificado | H30: Não verificado
A31: =DATE(Configurações!$B$3,5,2) -> 46144 | B31: =TEXT(A31,"ddd") -> sáb | C31: =Configurações!$A$9 -> CAM 03 | D31: =Configurações!$B$9 -> Câmera 03 | E31: =Configurações!$C$9 -> 0 | F31: Não verificado | G31: Não verificado | H31: Não verificado
A32: =DATE(Configurações!$B$3,5,2) -> 46144 | B32: =TEXT(A32,"ddd") -> sáb | C32: =Configurações!$A$10 -> CAM 04 | D32: =Configurações!$B$10 -> Câmera 04 | E32: =Configurações!$C$10 -> 0 | F32: Não verificado | G32: Não verificado | H32: Não verificado
A33: =DATE(Configurações!$B$3,5,2) -> 46144 | B33: =TEXT(A33,"ddd") -> sáb | C33: =Configurações!$A$11 -> CAM 05 | D33: =Configurações!$B$11 -> Câmera 05 | E33: =Configurações!$C$11 -> 0 | F33: Não verificado | G33: Não verificado | H33: Não verificado
A34: =DATE(Configurações!$B$3,5,2) -> 46144 | B34: =TEXT(A34,"ddd") -> sáb | C34: =Configurações!$A$12 -> CAM 06 | D34: =Configurações!$B$12 -> Câmera 06 | E34: =Configurações!$C$12 -> 0 | F34: Não verificado | G34: Não verificado | H34: Não verificado
A35: =DATE(Configurações!$B$3,5,2) -> 46144 | B35: =TEXT(A35,"ddd") -> sáb | C35: =Configurações!$A$13 -> CAM 07 | D35: =Configurações!$B$13 -> Câmera 07 | E35: =Configurações!$C$13 -> 0 | F35: Não verificado | G35: Não verificado | H35: Não verificado
A36: =DATE(Configurações!$B$3,5,2) -> 46144 | B36: =TEXT(A36,"ddd") -> sáb | C36: =Configurações!$A$14 -> CAM 08 | D36: =Configurações!$B$14 -> Câmera 08 | E36: =Configurações!$C$14 -> 0 | F36: Não verificado | G36: Não verificado | H36: Não verificado
A37: =DATE(Configurações!$B$3,5,2) -> 46144 | B37: =TEXT(A37,"ddd") -> sáb | C37: =Configurações!$A$15 -> CAM 09 | D37: =Configurações!$B$15 -> Câmera 09 | E37: =Configurações!$C$15 -> 0 | F37: Não verificado | G37: Não verificado | H37: Não verificado
A38: =DATE(Configurações!$B$3,5,2) -> 46144 | B38: =TEXT(A38,"ddd") -> sáb | C38: =Configurações!$A$16 -> CAM 10 | D38: =Configurações!$B$16 -> Câmera 10 | E38: =Configurações!$C$16 -> 0 | F38: Não verificado | G38: Não verificado | H38: Não verificado
A39: =DATE(Configurações!$B$3,5,2) -> 46144 | B39: =TEXT(A39,"ddd") -> sáb | C39: =Configurações!$A$17 -> CAM 11 | D39: =Configurações!$B$17 -> Câmera 11 | E39: =Configurações!$C$17 -> 0 | F39: Não verificado | G39: Não verificado | H39: Não verificado
A40: =DATE(Configurações!$B$3,5,2) -> 46144 | B40: =TEXT(A40,"ddd") -> sáb | C40: =Configurações!$A$18 -> CAM 12 | D40: =Configurações!$B$18 -> Câmera 12 | E40: =Configurações!$C$18 -> 0 | F40: Não verificado | G40: Não verificado | H40: Não verificado
A41: =DATE(Configurações!$B$3,5,2) -> 46144 | B41: =TEXT(A41,"ddd") -> sáb | C41: =Configurações!$A$19 -> CAM 13 | D41: =Configurações!$B$19 -> Câmera 13 | E41: =Configurações!$C$19 -> 0 | F41: Não verificado | G41: Não verificado | H41: Não verificado
...

Sheet Junho
A1: CONTROLE DE MONITORAMENTO DE CÂMERAS - JUNHO
A2: Status por horário: Online / Offline / Manutenção / Não verificado. Campo livre para evento técnico e comportamento do colaborador.
M4: RESUMO DO MÊS
A5: Data | B5: Dia | C5: ID | D5: Nome da Câmera | E5: Embarcação/Local | F5: 10:00 | G5: 13:00 | H5: 16:00 | I5: Evento Técnico Online/Offline | J5: Comportamento do Colaborador | K5: Responsável | M5: Indicador | N5: Total | O5: % | P5: Meta | Q5: Observação
A6: =DATE(Configurações!$B$3,6,1) -> 46174 | B6: =TEXT(A6,"ddd") -> seg | C6: =Configurações!$A$7 -> CAM 01 | D6: =Configurações!$B$7 -> BARU ANDES | E6: =Configurações!$C$7 -> 0 | F6: Não verificado | G6: Não verificado | H6: Não verificado | M6: Online | N6: =COUNTIF(F6:H718,"Online") -> 0 | O6: =IFERROR(N6/(N6+N7+N8),0) -> 0 | P6: >=95%
A7: =DATE(Configurações!$B$3,6,1) -> 46174 | B7: =TEXT(A7,"ddd") -> seg | C7: =Configurações!$A$8 -> CAM 02 | D7: =Configurações!$B$8 -> Câmera 02 | E7: =Configurações!$C$8 -> 0 | F7: Não verificado | G7: Não verificado | H7: Não verificado | M7: Offline | N7: =COUNTIF(F6:H718,"Offline") -> 0 | O7: =IFERROR(N7/(N6+N7+N8),0) -> 0 | P7: <=5%
A8: =DATE(Configurações!$B$3,6,1) -> 46174 | B8: =TEXT(A8,"ddd") -> seg | C8: =Configurações!$A$9 -> CAM 03 | D8: =Configurações!$B$9 -> Câmera 03 | E8: =Configurações!$C$9 -> 0 | F8: Não verificado | G8: Não verificado | H8: Não verificado | M8: Manutenção | N8: =COUNTIF(F6:H718,"Manutenção") -> 0 | O8: =IFERROR(N8/(N6+N7+N8),0) -> 0
A9: =DATE(Configurações!$B$3,6,1) -> 46174 | B9: =TEXT(A9,"ddd") -> seg | C9: =Configurações!$A$10 -> CAM 04 | D9: =Configurações!$B$10 -> Câmera 04 | E9: =Configurações!$C$10 -> 0 | F9: Não verificado | G9: Não verificado | H9: Não verificado | M9: Não verificado | N9: =COUNTIF(F6:H718,"Não verificado") -> 2139 | O9: =IFERROR(N9/(N6+N7+N8+N9),0) -> 1 | P9: zerar no fechamento
A10: =DATE(Configurações!$B$3,6,1) -> 46174 | B10: =TEXT(A10,"ddd") -> seg | C10: =Configurações!$A$11 -> CAM 05 | D10: =Configurações!$B$11 -> Câmera 05 | E10: =Configurações!$C$11 -> 0 | F10: Não verificado | G10: Não verificado | H10: Não verificado | M10: Eventos registrados | N10: =COUNTA(I6:J718) -> 0
A11: =DATE(Configurações!$B$3,6,1) -> 46174 | B11: =TEXT(A11,"ddd") -> seg | C11: =Configurações!$A$12 -> CAM 06 | D11: =Configurações!$B$12 -> Câmera 06 | E11: =Configurações!$C$12 -> 0 | F11: Não verificado | G11: Não verificado | H11: Não verificado
A12: =DATE(Configurações!$B$3,6,1) -> 46174 | B12: =TEXT(A12,"ddd") -> seg | C12: =Configurações!$A$13 -> CAM 07 | D12: =Configurações!$B$13 -> Câmera 07 | E12: =Configurações!$C$13 -> 0 | F12: Não verificado | G12: Não verificado | H12: Não verificado
A13: =DATE(Configurações!$B$3,6,1) -> 46174 | B13: =TEXT(A13,"ddd") -> seg | C13: =Configurações!$A$14 -> CAM 08 | D13: =Configurações!$B$14 -> Câmera 08 | E13: =Configurações!$C$14 -> 0 | F13: Não verificado | G13: Não verificado | H13: Não verificado
A14: =DATE(Configurações!$B$3,6,1) -> 46174 | B14: =TEXT(A14,"ddd") -> seg | C14: =Configurações!$A$15 -> CAM 09 | D14: =Configurações!$B$15 -> Câmera 09 | E14: =Configurações!$C$15 -> 0 | F14: Não verificado | G14: Não verificado | H14: Não verificado
A15: =DATE(Configurações!$B$3,6,1) -> 46174 | B15: =TEXT(A15,"ddd") -> seg | C15: =Configurações!$A$16 -> CAM 10 | D15: =Configurações!$B$16 -> Câmera 10 | E15: =Configurações!$C$16 -> 0 | F15: Não verificado | G15: Não verificado | H15: Não verificado
A16: =DATE(Configurações!$B$3,6,1) -> 46174 | B16: =TEXT(A16,"ddd") -> seg | C16: =Configurações!$A$17 -> CAM 11 | D16: =Configurações!$B$17 -> Câmera 11 | E16: =Configurações!$C$17 -> 0 | F16: Não verificado | G16: Não verificado | H16: Não verificado
